terminate called after throwing an instance of 'cv::Exception'
terminate called recursively
  what():  OpenCV(4.5.1-dev) /opt/opencv/modules/imgproc/src/color.cpp:182: error: (-215:Assertion failed) !_src.empty() in function 'cvtColor'

terminate called recursively
terminate called recursively
Command terminated by signal 6
	Command being timed: "./optimise ../Subtask2/trafficvideo.mp4 4 12"
	User time (seconds): 78.73
	System time (seconds): 0.66
	Percent of CPU this job got: 306%
	Elapsed (wall clock) time (h:mm:ss or m:ss): 0:25.87
	Average shared text size (kbytes): 0
	Average unshared data size (kbytes): 0
	Average stack size (kbytes): 0
	Average total size (kbytes): 0
	Maximum resident set size (kbytes): 167640
	Average resident set size (kbytes): 0
	Major (requiring I/O) page faults: 0
	Minor (reclaiming a frame) page faults: 38791
	Voluntary context switches: 62946
	Involuntary context switches: 1988
	Swaps: 0
	File system inputs: 0
	File system outputs: 8
	Socket messages sent: 0
	Socket messages received: 0
	Signals delivered: 0
	Page size (bytes): 4096
	Exit status: 0
